<sdf version='1.3'>
  <world name='default'>
    <light name='sun' type='directional'>
      <cast_shadows>1</cast_shadows>
      <pose>0.000000 0.000000 10.000000 0.000000 0.000000 0.000000</pose>
      <diffuse>0.800000 0.800000 0.800000 1.000000</diffuse>
      <specular>0.100000 0.100000 0.100000 1.000000</specular>
      <attenuation>
        <range>1000.000000</range>
        <constant>0.900000</constant>
        <linear>0.010000</linear>
        <quadratic>0.001000</quadratic>
      </attenuation>
      <direction>-0.500000 0.500000 -1.000000</direction>
    </light>
    <model name='ground_plane'>
      <static>1</static>
      <link name='link'>
        <collision name='collision'>
          <geometry>
            <plane>
              <normal>0.000000 0.000000 1.000000</normal>
              <size>100.000000 100.000000</size>
            </plane>
          </geometry>
          <surface>
            <friction>
              <ode>
                <mu>100.000000</mu>
                <mu2>50.000000</mu2>
              </ode>
            </friction>
            <bounce/>
            <contact>
              <ode/>
            </contact>
          </surface>
        </collision>
        <visual name='visual'>
          <cast_shadows>0</cast_shadows>
          <geometry>
            <plane>
              <normal>0.000000 0.000000 1.000000</normal>
              <size>100.000000 100.000000</size>
            </plane>
          </geometry>
          <material>
            <script>
              <uri>file://media/materials/scripts/gazebo.material</uri>
              <name>Gazebo/Grey</name>
            </script>
          </material>
        </visual>
        <velocity_decay>
          <linear>0.000000</linear>
          <angular>0.000000</angular>
        </velocity_decay>
        <self_collide>0</self_collide>
        <kinematic>0</kinematic>
        <gravity>1</gravity>
      </link>
    </model>
    <physics type='ode'>
      <update_rate>1000.000000</update_rate>
      <gravity>0.000000 0.000000 -9.800000</gravity>
    </physics>
    <scene>
      <ambient>0.200000 0.200000 0.200000 1.000000</ambient>
      <background>0.700000 0.700000 0.700000 1.000000</background>
      <shadows>1</shadows>
    </scene>
    <model name='willowgarage'>
      <static>1</static>
      <pose>-20.000000 -20.000000 0.000000 0.000000 0.000000 0.000000</pose>
      <link name='walls'>
        <collision name='collision'>
          <geometry>
            <mesh>
              <uri>model://willowgarage/meshes/willowgarage_collision.dae</uri>
            </mesh>
          </geometry>
          <surface>
            <bounce/>
            <friction>
              <ode/>
            </friction>
            <contact>
              <ode/>
            </contact>
          </surface>
        </collision>
        <visual name='visual'>
          <geometry>
            <mesh>
              <uri>model://willowgarage/meshes/willowgarage_visual.dae</uri>
            </mesh>
          </geometry>
          <cast_shadows>0</cast_shadows>
        </visual>
        <velocity_decay>
          <linear>0.000000</linear>
          <angular>0.000000</angular>
        </velocity_decay>
        <self_collide>0</self_collide>
        <kinematic>0</kinematic>
        <gravity>1</gravity>
      </link>
    </model>
    <model name='Pioneer3AT'>
      <pose>-9.00000 -22.00000 0.1720000 0.000000 0.000000 90.00000</pose>
      <static>0</static>
      <link name='chassis'>
        <inertial>
          <mass>14.000000</mass>
          <inertia>
            <ixx>0.333800</ixx>
            <ixy>0.000000</ixy>
            <ixz>0.000000</ixz>
            <iyy>0.478300</iyy>
            <iyz>0.000000</iyz>
            <izz>0.333800</izz>
          </inertia>
        </inertial>
        <collision name='collision'>
          <geometry>
            <box>
              <size>0.501000 0.400000 0.190000</size>
            </box>
          </geometry>
          <surface>
            <bounce/>
            <friction>
              <ode/>
            </friction>
            <contact>
              <ode/>
            </contact>
          </surface>
        </collision>
        <visual name='visual'>
          <geometry>
            <mesh>
              <uri>model://pioneer3at/meshes/chassis.dae</uri>
            </mesh>
          </geometry>
        </visual>
        <velocity_decay>
          <linear>0.000000</linear>
          <angular>0.000000</angular>
        </velocity_decay>
        <self_collide>0</self_collide>
        <kinematic>0</kinematic>
        <gravity>1</gravity>
      </link>
      <link name='right_front_wheel'>
        <pose>0.125000 -0.201000 -0.060000 1.570700 0.000000 0.000000</pose>
        <collision name='collision'>
          <geometry>
            <cylinder>
              <radius>0.110000</radius>
              <length>0.075000</length>
            </cylinder>
          </geometry>
          <surface>
            <friction>
              <ode>
                <mu>1.000000</mu>
                <mu2>1.000000</mu2>
                <slip1>0.500000</slip1>
                <slip2>0.000000</slip2>
              </ode>
            </friction>
            <bounce/>
            <contact>
              <ode/>
            </contact>
          </surface>
        </collision>
        <visual name='visual'>
          <geometry>
            <mesh>
              <uri>model://pioneer3at/meshes/wheel.dae</uri>
            </mesh>
          </geometry>
        </visual>
        <velocity_decay>
          <linear>0.000000</linear>
          <angular>0.000000</angular>
        </velocity_decay>
        <self_collide>0</self_collide>
        <inertial>
          <inertia>
            <ixx>1.000000</ixx>
            <ixy>0.000000</ixy>
            <ixz>0.000000</ixz>
            <iyy>1.000000</iyy>
            <iyz>0.000000</iyz>
            <izz>1.000000</izz>
          </inertia>
          <mass>1.000000</mass>
        </inertial>
        <kinematic>0</kinematic>
        <gravity>1</gravity>
      </link>
      <link name='left_front_wheel'>
        <pose>0.125000 0.201000 -0.060000 1.570700 0.000000 0.000000</pose>
        <collision name='collision'>
          <geometry>
            <cylinder>
              <radius>0.110000</radius>
              <length>0.075000</length>
            </cylinder>
          </geometry>
          <surface>
            <friction>
              <ode>
                <mu>1.000000</mu>
                <mu2>1.000000</mu2>
                <slip1>0.500000</slip1>
                <slip2>0.000000</slip2>
              </ode>
            </friction>
            <bounce/>
            <contact>
              <ode/>
            </contact>
          </surface>
        </collision>
        <visual name='visual'>
          <geometry>
            <mesh>
              <uri>model://pioneer3at/meshes/wheel.dae</uri>
            </mesh>
          </geometry>
        </visual>
        <velocity_decay>
          <linear>0.000000</linear>
          <angular>0.000000</angular>
        </velocity_decay>
        <self_collide>0</self_collide>
        <inertial>
          <inertia>
            <ixx>1.000000</ixx>
            <ixy>0.000000</ixy>
            <ixz>0.000000</ixz>
            <iyy>1.000000</iyy>
            <iyz>0.000000</iyz>
            <izz>1.000000</izz>
          </inertia>
          <mass>1.000000</mass>
        </inertial>
        <kinematic>0</kinematic>
        <gravity>1</gravity>
      </link>
      <link name='right_rear_wheel'>
        <pose>-0.125000 -0.201000 -0.060000 1.570700 0.000000 0.000000</pose>
        <collision name='collision'>
          <geometry>
            <cylinder>
              <radius>0.110000</radius>
              <length>0.075000</length>
            </cylinder>
          </geometry>
          <surface>
            <friction>
              <ode>
                <mu>1.000000</mu>
                <mu2>1.000000</mu2>
                <slip1>0.500000</slip1>
                <slip2>0.000000</slip2>
              </ode>
            </friction>
            <bounce/>
            <contact>
              <ode/>
            </contact>
          </surface>
        </collision>
        <visual name='visual'>
          <geometry>
            <mesh>
              <uri>model://pioneer3at/meshes/wheel.dae</uri>
            </mesh>
          </geometry>
        </visual>
        <velocity_decay>
          <linear>0.000000</linear>
          <angular>0.000000</angular>
        </velocity_decay>
        <self_collide>0</self_collide>
        <inertial>
          <inertia>
            <ixx>1.000000</ixx>
            <ixy>0.000000</ixy>
            <ixz>0.000000</ixz>
            <iyy>1.000000</iyy>
            <iyz>0.000000</iyz>
            <izz>1.000000</izz>
          </inertia>
          <mass>1.000000</mass>
        </inertial>
        <kinematic>0</kinematic>
        <gravity>1</gravity>
      </link>
      <link name='left_rear_wheel'>
        <pose>-0.125000 0.201000 -0.060000 1.570700 0.000000 0.000000</pose>
        <collision name='collision'>
          <geometry>
            <cylinder>
              <radius>0.110000</radius>
              <length>0.075000</length>
            </cylinder>
          </geometry>
          <surface>
            <friction>
              <ode>
                <mu>1.000000</mu>
                <mu2>1.000000</mu2>
                <slip1>0.500000</slip1>
                <slip2>0.000000</slip2>
              </ode>
            </friction>
            <bounce/>
            <contact>
              <ode/>
            </contact>
          </surface>
        </collision>
        <visual name='visual'>
          <geometry>
            <mesh>
              <uri>model://pioneer3at/meshes/wheel.dae</uri>
            </mesh>
          </geometry>
        </visual>
        <velocity_decay>
          <linear>0.000000</linear>
          <angular>0.000000</angular>
        </velocity_decay>
        <self_collide>0</self_collide>
        <inertial>
          <inertia>
            <ixx>1.000000</ixx>
            <ixy>0.000000</ixy>
            <ixz>0.000000</ixz>
            <iyy>1.000000</iyy>
            <iyz>0.000000</iyz>
            <izz>1.000000</izz>
          </inertia>
          <mass>1.000000</mass>
        </inertial>
        <kinematic>0</kinematic>
        <gravity>1</gravity>
      </link>
      <joint name='right_front' type='revolute'>
        <pose>0.000000 0.000000 0.000000 0.000000 0.000000 0.000000</pose>
        <child>right_front_wheel</child>
        <parent>chassis</parent>
        <axis>
          <xyz>0.000000 1.000000 0.000000</xyz>
          <limit>
            <lower>-10000000000000000.000000</lower>
            <upper>10000000000000000.000000</upper>
          </limit>
        </axis>
      </joint>
      <joint name='right_rear' type='revolute'>
        <pose>0.000000 0.000000 0.000000 0.000000 0.000000 0.000000</pose>
        <child>right_rear_wheel</child>
        <parent>chassis</parent>
        <axis>
          <xyz>0.000000 1.000000 0.000000</xyz>
          <limit>
            <lower>-10000000000000000.000000</lower>
            <upper>10000000000000000.000000</upper>
          </limit>
        </axis>
      </joint>
      <joint name='left_front' type='revolute'>
        <pose>0.000000 0.000000 0.000000 0.000000 0.000000 0.000000</pose>
        <child>left_front_wheel</child>
        <parent>chassis</parent>
        <axis>
          <xyz>0.000000 1.000000 0.000000</xyz>
          <limit>
            <lower>-10000000000000000.000000</lower>
            <upper>10000000000000000.000000</upper>
          </limit>
        </axis>
      </joint>
      <joint name='left_rear' type='revolute'>
        <pose>0.000000 0.000000 0.000000 0.000000 0.000000 0.000000</pose>
        <child>left_rear_wheel</child>
        <parent>chassis</parent>
        <axis>
          <xyz>0.000000 1.000000 0.000000</xyz>
          <limit>
            <lower>-10000000000000000.000000</lower>
            <upper>10000000000000000.000000</upper>
          </limit>
        </axis>
      </joint>
      <link name='hokuyo::link'>
        <inertial>
          <mass>0.100000</mass>
          <inertia>
            <ixx>1.000000</ixx>
            <ixy>0.000000</ixy>
            <ixz>0.000000</ixz>
            <iyy>1.000000</iyy>
            <iyz>0.000000</iyz>
            <izz>1.000000</izz>
          </inertia>
        </inertial>
        <visual name='visual'>
          <geometry>
            <mesh>
              <uri>model://hokuyo/meshes/hokuyo.dae</uri>
            </mesh>
          </geometry>
        </visual>
        <collision name='collision-base'>
          <pose>0.000000 0.000000 -0.014500 0.000000 0.000000 0.000000</pose>
          <geometry>
            <box>
              <size>0.050000 0.050000 0.041000</size>
            </box>
          </geometry>
          <surface>
            <bounce/>
            <friction>
              <ode/>
            </friction>
            <contact>
              <ode/>
            </contact>
          </surface>
        </collision>
        <collision name='collision-top'>
          <pose>0.000000 0.000000 0.020500 0.000000 0.000000 0.000000</pose>
          <geometry>
            <cylinder>
              <radius>0.021000</radius>
              <length>0.029000</length>
            </cylinder>
          </geometry>
          <surface>
            <bounce/>
            <friction>
              <ode/>
            </friction>
            <contact>
              <ode/>
            </contact>
          </surface>
        </collision>
        <sensor name='laser' type='ray'>
          <pose>0.010000 0.000000 0.017500 0.000000 0.000000 0.000000</pose>
          <ray>
            <scan>
              <horizontal>
                <samples>640</samples>
                <resolution>1.000000</resolution>
                <min_angle>-2.268890</min_angle>
                <max_angle>2.268899</max_angle>
              </horizontal>
            </scan>
            <range>
              <min>0.080000</min>
              <max>10.000000</max>
              <resolution>0.010000</resolution>
            </range>
          </ray>
          <plugin name='laser' filename='libRayPlugin.so'/>
          <always_on>1</always_on>
          <update_rate>30.000000</update_rate>
          <visualize>1</visualize>
        </sensor>
        <velocity_decay>
          <linear>0.000000</linear>
          <angular>0.000000</angular>
        </velocity_decay>
        <pose>0.200000 0.000000 0.130000 0.000000 0.000000 0.000000</pose>
        <self_collide>0</self_collide>
        <kinematic>0</kinematic>
        <gravity>1</gravity>
      </link>
      <joint name='hokuyo_joint' type='revolute'>
        <child>hokuyo::link</child>
        <parent>chassis</parent>
        <axis>
          <xyz>0.000000 0.000000 1.000000</xyz>
          <limit>
            <upper>0.000000</upper>
            <lower>0.000000</lower>
          </limit>
        </axis>
      </joint>
      
    <!-- Camera -->  
    <link name="kinect::link">
    	<pose>0.2 0 0.265 0 0 0</pose>
     	<inertial>
        <mass>0.1</mass>
     	</inertial>
     	<collision name="collision">
        	<geometry>
          		<box>
            	<size>0.073000 0.276000 0.072000</size>
         		</box>
        	</geometry>
     	</collision>
      	<visual name="visual">
        	<geometry>
          		<mesh>
            		<uri>model://kinect/meshes/kinect.dae</uri>
          		</mesh>
        	</geometry>
      	</visual>

      <sensor type="depth" name="camera1">
       <always_on>1</always_on>
       <visualize>true</visualize>
      	<update_rate>30.0</update_rate>
      	<topic>camera</topic>
      	<camera name="depth_cam">
       		 <horizontal_fov>1.3962634</horizontal_fov>
        	<image>
          		<width>800</width>
         		 <height>800</height>
          		<format>R8G8B8</format>
       		 </image>
        	<clip>
          		<near>0.02</near>
          		<far>300</far>
        	</clip>
        	<noise>
         		 <type>gaussian</type>
          			<!-- Noise is sampled independently per pixel on each frame.  
               		That pixel's noise value is added to each of its color
               		channels, which at that point lie in the range [0,1]. -->
          		<mean>0.0</mean>
          		<stddev>0.007</stddev>
       		 </noise>
        	<save enabled=true>  <!-- Nose que es esto -->
        	 	<path>Gazebo_camera</path>
        	</save>
      </camera>
      <plugin name="camera_controller" filename="libDepthCameraPlugin.so">
        <CxPrime>0</CxPrime>
		<updateRate>10.0</updateRate>
    	<cameraName>depth_cam1</cameraName>
    	<frameName>/Pioneer3AT/kinect</frameName>
        <hackBaseline>0.07</hackBaseline>
        <distortionK1>1.0</distortionK1>
        <distortionK2>1.0</distortionK2>
        <distortionK3>1.0</distortionK3>
        <distortionT1>1.0</distortionT1>
        <distortionT2>1.0</distortionT2>
      </plugin>
     <plugin name="kinect" filename="libgazebo_ros_openni_kinect.so">
     	<CxPrime>0</CxPrime>
		<updateRate>10.0</updateRate>
		<imageTopicName>image_raw</imageTopicName>
    	<pointCloudTopicName>points</pointCloudTopicName>
    	<depthImageTopicName>image_depth</depthImageTopicName>
    	<depthImageCameraInfoTopicName>camera_info</depthImageCameraInfoTopicName>
    	<pointCloudCutoff>0.001</pointCloudCutoff>
    	<cameraName>kinect</cameraName>
    	<frameName>/Pioneer3AT/kinect</frameName>
		<distortionK1>0.00000001</distortionK1>
    	<distortionK2>0.00000001</distortionK2>
    	<distortionK3>0.00000001</distortionK3>
    	<distortionT1>0.00000001</distortionT1>
  	 	<distortionT2>0.00000001</distortionT2>
      </plugin>
    </sensor>
    </link>
     
      <joint name="kinect_joint" type="revolute">
        <child>kinect::link</child>
        <parent>chassis</parent>
        <axis>
          <xyz>0 0 1</xyz>
          <limit>
            <upper>0</upper>
            <lower>0</lower>
          </limit>
        </axis>
      </joint>
      
    <plugin name='SkidSteerDrivePlugin' filename='libSkidSteerDrivePlugin.so'/>
    </model>
    
    <state world_name='default'>
      <sim_time>0 0</sim_time>
      <real_time>0 0</real_time>
      <wall_time>0 0</wall_time>
    </state>
    <gui fullscreen='0'>
      <camera name='user_camera'>
        <pose>-11.114900 -38.921000 27.657300 -0.000000 0.815643 1.052190</pose>
        <view_controller>orbit</view_controller>
      </camera>
    </gui>
  </world>
</sdf>
